<robot name="dodobot">
  <material name="white">
    <color rgba="1 1 1 1"/>
  </material>

  <material name="blue">
    <color rgba="0 0.369 0.722 1"/>
  </material>

  <link name="base_link">
    <visual>
      <origin rpy="0 0 0" xyz="0 0 0"/>
      <geometry>
        <mesh filename="package://db_support/meshes/chassis.stl"/>
      </geometry>
      <material name="blue"/>
    </visual>
  </link>

  <link name="tilt_base_link">
  </link>

  <joint name="base_link_to_tilt_base_joint" type="fixed">
    <parent link="base_link"/>
    <child link="tilt_base_link"/>
    <origin xyz="0.04796 0.0 0.24785"/>
  </joint>

  <joint name="tilt_base_to_camera_rotate_joint" type="revolute">
    <parent link="tilt_base_link"/>
    <child link="camera_rotate_link"/>
    <origin xyz="0 0 0"/>
    <limit effort="1000.0" lower="0.0" upper="0.548" velocity="0.5"/>
    <axis xyz="0 1 0"/>
  </joint>

  <link name="camera_rotate_link">
    <visual>
      <origin rpy="0 0 0" xyz="0 0 0"/>
      <geometry>
        <mesh filename="package://db_support/meshes/camera.stl"/>
      </geometry>
      <material name="white"/>
    </visual>
  </link>

  <link name="linear_base_link">
  </link>

  <joint name="linear_base_to_base_link" type="fixed">
    <parent link="base_link"/>
    <child link="linear_base_link"/>
    <origin xyz="0.06046488 0.0 0.01825032"/>
  </joint>

  <joint name="linear_to_linear_base_link" type="prismatic">
    <parent link="linear_base_link"/>
    <child link="linear_link"/>
    <origin xyz="0 0 0"/>
    <axis xyz="0 0 1"/>
    <limit effort="1000.0" lower="0" upper="0.154" velocity="0.5"/>
  </joint>

  <link name="linear_link">
    <visual>
      <origin rpy="0 0 0" xyz="0 0 0"/>
      <geometry>
        <mesh filename="package://db_support/meshes/gripper.stl"/>
      </geometry>
      <material name="white"/>
    </visual>
  </link>
</robot>
